Workbook
Name NativeTimeline_ORDER_DATE: #N/A
Name Slicer_PRODUCT_CATEGORY: #N/A
Name Slicer_REGION: #N/A

Sheet DASHBOARD
C1: SALES PERFORMANCE DASHBOARD
C3: Analyze | Visualize | Grow
U14: =GETPIVOTDATA("Sum of SALES",'PIVOT TABLES'!$A$4) -> 195217.76
U15: ='PIVOT TABLES'!A26 -> 68287.01
T19: ='PIVOT TABLES'!A26 -> 68287.01
T22: ='PIVOT TABLES'!C30 -> 0
T28: ='PIVOT TABLES'!C30 -> 0
T31: ='PIVOT TABLES'!F30 -> 0

Sheet ANALYZER_DATA
A1: CUSTOMER_ID | B1: CUSTOMER_NAME | C1: REGION | D1: PRODUCT_CATEGORY | E1: SALES | F1: QUANTITY | G1: DISCOUNT | H1: ORDER_DATE | I1: PROFIT | J1: TOTAL_PURCHASE | K1: TIMESTAMP
A2: CUST019 | B2: James Davis | C2: West | D2: Books | E2: 1036.09 | F2: 4 | G2: 0.2 | H2: 45392 | I2: 331.55 | J2: =SUMIF($A$2:$A$201,A2,$E$2:$E$201) -> 4640.11 | K2: =NOW() -> 46287.008
A3: CUST012 | B3: Robert Anderson | C3: West | D3: Clothing | E3: 1101.28 | F3: 3 | G3: 0.2 | H3: 45393 | I3: 440.51 | J3: =SUMIF($A$2:$A$201,A3,$E$2:$E$201) -> 8339 | K3: =NOW() -> 46287.008
A4: CUST017 | B4: James Taylor | C4: East | D4: Books | E4: 713.34 | F4: 17 | G4: 0 | H4: 45396 | I4: 285.34 | J4: =SUMIF($A$2:$A$201,A4,$E$2:$E$201) -> 3419.2 | K4: =NOW() -> 46287.008
A5: CUST005 | B5: Robert Anderson | C5: South | D5: Electronics | E5: 760.93 | F5: 4 | G5: 0.15 | H5: 45396 | I5: 161.7 | J5: =SUMIF($A$2:$A$201,A5,$E$2:$E$201) -> 6666.13 | K5: =NOW() -> 46287.008 | M5: TOP 10 CUSTOMER
A6: CUST030 | B6: James Wilson | C6: North | D6: Books | E6: 847 | F6: 12 | G6: 0.2 | H6: 45397 | I6: 271.04 | J6: =SUMIF($A$2:$A$201,A6,$E$2:$E$201) -> 7928.71 | K6: =NOW() -> 46287.008 | M6: CUSTOMER ID | N6: CUSTOMER NAME | O6: TOTAL PURCHASE
A7: CUST007 | B7: Michael Anderson | C7: North | D7: Furniture | E7: 965.64 | F7: 8 | G7: 0.1 | H7: 45398 | I7: 304.18 | J7: =SUMIF($A$2:$A$201,A7,$E$2:$E$201) -> 9941.88 | K7: =NOW() -> 46287.008 | M7: =INDEX(A2:A201,MATCH(O7,J2:J201,0)) -> CUST015 | N7: =INDEX(B2:B201,MATCH(O7,J2:J201,0)) -> Linda Taylor | O7: =LARGE(_xlfn.UNIQUE($J$2:$J$201),ROWS($O$7:O7)) -> 11611.06
A8: CUST001 | B8: Linda Wilson | C8: West | D8: Electronics | E8: 1317.53 | F8: 12 | G8: 0.05 | H8: 45398 | I8: 312.91 | J8: =SUMIF($A$2:$A$201,A8,$E$2:$E$201) -> 6549.55 | K8: =NOW() -> 46287.008 | M8: =INDEX(A3:A202,MATCH(O8,J3:J202,0)) -> CUST028 | N8: =INDEX(B3:B202,MATCH(O8,J3:J202,0)) -> Linda Taylor | O8: =LARGE(_xlfn.UNIQUE($J$2:$J$201),ROWS($O$7:O8)) -> 10293.87
A9: CUST026 | B9: Mary Davis | C9: East | D9: Furniture | E9: 1074.47 | F9: 6 | G9: 0.2 | H9: 45401 | I9: 300.85 | J9: =SUMIF($A$2:$A$201,A9,$E$2:$E$201) -> 9371.81 | K9: =NOW() -> 46287.008 | M9: =INDEX(A4:A203,MATCH(O9,J4:J203,0)) -> CUST007 | N9: =INDEX(B4:B203,MATCH(O9,J4:J203,0)) -> Michael Anderson | O9: =LARGE(_xlfn.UNIQUE($J$2:$J$201),ROWS($O$7:O9)) -> 9941.88
A10: CUST009 | B10: Linda Jackson | C10: Central | D10: Books | E10: 501.54 | F10: 11 | G10: 0.05 | H10: 45401 | I10: 190.59 | J10: =SUMIF($A$2:$A$201,A10,$E$2:$E$201) -> 6505.2 | K10: =NOW() -> 46287.008 | M10: =INDEX(A5:A204,MATCH(O10,J5:J204,0)) -> CUST008 | N10: =INDEX(B5:B204,MATCH(O10,J5:J204,0)) -> Robert Anderson | O10: =LARGE(_xlfn.UNIQUE($J$2:$J$201),ROWS($O$7:O10)) -> 9760.8
A11: CUST010 | B11: David Thomas | C11: Central | D11: Clothing | E11: 737.31 | F11: 2 | G11: 0.05 | H11: 45401 | I11: 350.22 | J11: =SUMIF($A$2:$A$201,A11,$E$2:$E$201) -> 4259.22 | K11: =NOW() -> 46287.008 | M11: =INDEX(A6:A205,MATCH(O11,J6:J205,0)) -> CUST026 | N11: =INDEX(B6:B205,MATCH(O11,J6:J205,0)) -> Mary Davis | O11: =LARGE(_xlfn.UNIQUE($J$2:$J$201),ROWS($O$7:O11)) -> 9371.81
A12: CUST014 | B12: Emma Davis | C12: West | D12: Office Supplies | E12: 1572.82 | F12: 6 | G12: 0.05 | H12: 45402 | I12: 672.38 | J12: =SUMIF($A$2:$A$201,A12,$E$2:$E$201) -> 6729.89 | K12: =NOW() -> 46287.008 | M12: =INDEX(A7:A206,MATCH(O12,J7:J206,0)) -> CUST021 | N12: =INDEX(B7:B206,MATCH(O12,J7:J206,0)) -> Sarah Anderson | O12: =LARGE(_xlfn.UNIQUE($J$2:$J$201),ROWS($O$7:O12)) -> 8740.18
A13: CUST014 | B13: David Thomas | C13: Central | D13: Books | E13: 1343.13 | F13: 14 | G13: 0.15 | H13: 45404 | I13: 456.66 | J13: =SUMIF($A$2:$A$201,A13,$E$2:$E$201) -> 6729.89 | K13: =NOW() -> 46287.008 | M13: =INDEX(A8:A207,MATCH(O13,J8:J207,0)) -> CUST003 | N13: =INDEX(B8:B207,MATCH(O13,J8:J207,0)) -> Emma Davis | O13: =LARGE(_xlfn.UNIQUE($J$2:$J$201),ROWS($O$7:O13)) -> 8490.18
A14: CUST007 | B14: Michael Anderson | C14: Central | D14: Books | E14: 1191.58 | F14: 14 | G14: 0.05 | H14: 45406 | I14: 452.8 | J14: =SUMIF($A$2:$A$201,A14,$E$2:$E$201) -> 9941.88 | K14: =NOW() -> 46287.008 | M14: =INDEX(A9:A208,MATCH(O14,J9:J208,0)) -> CUST012 | N14: =INDEX(B9:B208,MATCH(O14,J9:J208,0)) -> Mary Davis | O14: =LARGE(_xlfn.UNIQUE($J$2:$J$201),ROWS($O$7:O14)) -> 8339
A15: CUST023 | B15: Robert Anderson | C15: West | D15: Furniture | E15: 822.28 | F15: 7 | G15: 0.05 | H15: 45406 | I15: 273.41 | J15: =SUMIF($A$2:$A$201,A15,$E$2:$E$201) -> 5913.68 | K15: =NOW() -> 46287.008 | M15: =INDEX(A10:A209,MATCH(O15,J10:J209,0)) -> CUST030 | N15: =INDEX(B10:B209,MATCH(O15,J10:J209,0)) -> John Brown | O15: =LARGE(_xlfn.UNIQUE($J$2:$J$201),ROWS($O$7:O15)) -> 7928.71
A16: CUST029 | B16: David Smith | C16: North | D16: Furniture | E16: 521.67 | F16: 15 | G16: 0.15 | H16: 45409 | I16: 155.2 | J16: =SUMIF($A$2:$A$201,A16,$E$2:$E$201) -> 5779.05 | K16: =NOW() -> 46287.008 | M16: =INDEX(A11:A210,MATCH(O16,J11:J210,0)) -> CUST004 | N16: =INDEX(B11:B210,MATCH(O16,J11:J210,0)) -> Lisa Thomas | O16: =LARGE(_xlfn.UNIQUE($J$2:$J$201),ROWS($O$7:O16)) -> 7813.59
A17: CUST005 | B17: Sarah Anderson | C17: South | D17: Electronics | E17: 1502.93 | F17: 14 | G17: 0.2 | H17: 45410 | I17: 300.59 | J17: =SUMIF($A$2:$A$201,A17,$E$2:$E$201) -> 6666.13 | K17: =NOW() -> 46287.008
A18: CUST008 | B18: Robert Anderson | C18: South | D18: Books | E18: 877.58 | F18: 10 | G18: 0.15 | H18: 45411 | I18: 298.38 | J18: =SUMIF($A$2:$A$201,A18,$E$2:$E$201) -> 9760.8 | K18: =NOW() -> 46287.008
A19: CUST001 | B19: Lisa Thomas | C19: West | D19: Books | E19: 636.7 | F19: 4 | G19: 0.2 | H19: 45411 | I19: 203.74 | J19: =SUMIF($A$2:$A$201,A19,$E$2:$E$201) -> 6549.55 | K19: =NOW() -> 46287.008 | M19: High-Value Customer
A20: CUST006 | B20: Mary Jackson | C20: West | D20: Books | E20: 1506.14 | F20: 13 | G20: 0.2 | H20: 45412 | I20: 481.96 | J20: =SUMIF($A$2:$A$201,A20,$E$2:$E$201) -> 2699.75 | K20: =NOW() -> 46287.008 | M20: CUSTOMER NAME | N20: REGION | O20: PRODUCT CATEGORY | P20: SALES | Q20: QUANTITY | R20: DISCOUNT | S20: ORDER DATE | T20: PROFIT | U20: TOTAL PURCHASE
A21: CUST026 | B21: Mary Davis | C21: Central | D21: Electronics | E21: 645.02 | F21: 4 | G21: 0 | H21: 45414 | I21: 161.26 | J21: =SUMIF($A$2:$A$201,A21,$E$2:$E$201) -> 9371.81 | K21: =NOW() -> 46287.008 | M21: {=_xlfn._xlws.FILTER($B$2:$J$201,$J$2:$J$201=MAX($J$2:$J$201))} -> Linda Taylor | N21: North | O21: Office Supplies | P21: 1200.9 | Q21: 14 | R21: 0.05 | S21: 45429 | T21: 513.38 | U21: 11611.06
A22: CUST007 | B22: Lisa Davis | C22: South | D22: Clothing | E22: 953.3 | F22: 11 | G22: 0 | H22: 45415 | I22: 476.65 | J22: =SUMIF($A$2:$A$201,A22,$E$2:$E$201) -> 9941.88 | K22: =NOW() -> 46287.008 | M22: James Wilson | N22: South | O22: Clothing | P22: 1226.62 | Q22: 7 | R22: 0.1 | S22: 45463 | T22: 551.98 | U22: 11611.06
A23: CUST022 | B23: Robert Anderson | C23: North | D23: Electronics | E23: 388.56 | F23: 14 | G23: 0.15 | H23: 45416 | I23: 82.57 | J23: =SUMIF($A$2:$A$201,A23,$E$2:$E$201) -> 4418.28 | K23: =NOW() -> 46287.008 | M23: David Thomas | N23: West | O23: Clothing | P23: 1168.89 | Q23: 4 | R23: 0.1 | S23: 45544 | T23: 526 | U23: 11611.06
A24: CUST019 | B24: Mary Davis | C24: West | D24: Books | E24: 743.17 | F24: 9 | G24: 0 | H24: 45416 | I24: 297.27 | J24: =SUMIF($A$2:$A$201,A24,$E$2:$E$201) -> 4640.11 | K24: =NOW() -> 46287.008 | M24: James Wilson | N24: West | O24: Clothing | P24: 1923.66 | Q24: 9 | R24: 0.2 | S24: 45580 | T24: 769.46 | U24: 11611.06
A25: CUST023 | B25: Mary Davis | C25: Central | D25: Electronics | E25: 706.37 | F25: 6 | G25: 0 | H25: 45416 | I25: 176.59 | J25: =SUMIF($A$2:$A$201,A25,$E$2:$E$201) -> 5913.68 | K25: =NOW() -> 46287.008 | M25: David Anderson | N25: West | O25: Furniture | P25: 820.19 | Q25: 4 | R25: 0.2 | S25: 45630 | T25: 229.65 | U25: 11611.06
A26: CUST012 | B26: Mary Davis | C26: Central | D26: Office Supplies | E26: 925.31 | F26: 8 | G26: 0.1 | H26: 45418 | I26: 374.75 | J26: =SUMIF($A$2:$A$201,A26,$E$2:$E$201) -> 8339 | K26: =NOW() -> 46287.008 | M26: Emma Davis | N26: Central | O26: Electronics | P26: 511.74 | Q26: 8 | R26: 0.05 | S26: 45631 | T26: 121.54 | U26: 11611.06
A27: CUST010 | B27: Linda Brown | C27: South | D27: Electronics | E27: 1173.12 | F27: 18 | G27: 0 | H27: 45418 | I27: 293.28 | J27: =SUMIF($A$2:$A$201,A27,$E$2:$E$201) -> 4259.22 | K27: =NOW() -> 46287.008 | M27: Robert Anderson | N27: South | O27: Furniture | P27: 1054.56 | Q27: 11 | R27: 0.1 | S27: 45669 | T27: 332.19 | U27: 11611.06
A28: CUST030 | B28: John Brown | C28: North | D28: Furniture | E28: 675.54 | F28: 17 | G28: 0 | H28: 45420 | I28: 236.44 | J28: =SUMIF($A$2:$A$201,A28,$E$2:$E$201) -> 7928.71 | K28: =NOW() -> 46287.008 | M28: James Wilson | N28: North | O28: Electronics | P28: 1681.21 | Q28: 5 | R28: 0.2 | S28: 45670 | T28: 336.24 | U28: 11611.06
A29: CUST007 | B29: Robert Anderson | C29: Central | D29: Books | E29: 939.09 | F29: 2 | G29: 0.05 | H29: 45422 | I29: 356.85 | J29: =SUMIF($A$2:$A$201,A29,$E$2:$E$201) -> 9941.88 | K29: =NOW() -> 46287.008 | M29: David Thomas | N29: West | O29: Clothing | P29: 379.77 | Q29: 9 | R29: 0.05 | S29: 45673 | T29: 180.39 | U29: 11611.06
A30: CUST028 | B30: Linda Taylor | C30: East | D30: Office Supplies | E30: 983.34 | F30: 19 | G30: 0.1 | H30: 45426 | I30: 398.25 | J30: =SUMIF($A$2:$A$201,A30,$E$2:$E$201) -> 10293.87 | K30: =NOW() -> 46287.008 | M30: Lisa Thomas | N30: East | O30: Books | P30: 1098.08 | Q30: 9 | R30: 0.1 | S30: 45692 | T30: 395.31 | U30: 11611.06
A31: CUST028 | B31: James Wilson | C31: South | D31: Electronics | E31: 801.21 | F31: 3 | G31: 0.2 | H31: 45426 | I31: 160.24 | J31: =SUMIF($A$2:$A$201,A31,$E$2:$E$201) -> 10293.87 | K31: =NOW() -> 46287.008 | M31: Sarah Anderson | N31: West | O31: Office Supplies | P31: 545.44 | Q31: 17 | R31: 0 | S31: 45752 | T31: 245.45 | U31: 11611.06
A32: CUST025 | B32: David Brown | C32: North | D32: Electronics | E32: 1450.71 | F32: 5 | G32: 0.1 | H32: 45427 | I32: 326.41 | J32: =SUMIF($A$2:$A$201,A32,$E$2:$E$201) -> 6716.52 | K32: =NOW() -> 46287.008
A33: CUST022 | B33: David Davis | C33: Central | D33: Books | E33: 1023.21 | F33: 18 | G33: 0.05 | H33: 45428 | I33: 388.82 | J33: =SUMIF($A$2:$A$201,A33,$E$2:$E$201) -> 4418.28 | K33: =NOW() -> 46287.008
A34: CUST001 | B34: Mary Jackson | C34: West | D34: Furniture | E34: 853.72 | F34: 5 | G34: 0.15 | H34: 45428 | I34: 253.98 | J34: =SUMIF($A$2:$A$201,A34,$E$2:$E$201) -> 6549.55 | K34: =NOW() -> 46287.008
A35: CUST021 | B35: Sarah Anderson | C35: South | D35: Electronics | E35: 967.89 | F35: 10 | G35: 0.1 | H35: 45429 | I35: 217.78 | J35: =SUMIF($A$2:$A$201,A35,$E$2:$E$201) -> 8740.18 | K35: =NOW() -> 46287.008
A36: CUST015 | B36: Linda Taylor | C36: North | D36: Office Supplies | E36: 1200.9 | F36: 14 | G36: 0.05 | H36: 45429 | I36: 513.38 | J36: =SUMIF($A$2:$A$201,A36,$E$2:$E$201) -> 11611.06 | K36: =NOW() -> 46287.008
A37: CUST012 | B37: Michael Anderson | C37: West | D37: Books | E37: 472.38 | F37: 12 | G37: 0.2 | H37: 45429 | I37: 151.16 | J37: =SUMIF($A$2:$A$201,A37,$E$2:$E$201) -> 8339 | K37: =NOW() -> 46287.008
A38: CUST019 | B38: David Brown | C38: East | D38: Office Supplies | E38: 840.92 | F38: 9 | G38: 0.05 | H38: 45429 | I38: 359.49 | J38: =SUMIF($A$2:$A$201,A38,$E$2:$E$201) -> 4640.11 | K38: =NOW() -> 46287.008
A39: CUST028 | B39: Lisa Davis | C39: Central | D39: Furniture | E39: 1410.06 | F39: 11 | G39: 0.05 | H39: 45434 | I39: 468.84 | J39: =SUMIF($A$2:$A$201,A39,$E$2:$E$201) -> 10293.87 | K39: =NOW() -> 46287.008
A40: CUST008 | B40: Mary Wilson | C40: Central | D40: Furniture | E40: 773.09 | F40: 13 | G40: 0.15 | H40: 45434 | I40: 229.99 | J40: =SUMIF($A$2:$A$201,A40,$E$2:$E$201) -> 9760.8 | K40: =NOW() -> 46287.008
...

Sheet MONTHLY SALES GROWTH
A1: MONTHS | B1: MONTHLY SALES | C1: SALES GROWTH
A2: 1 | B2: {=SUMPRODUCT((MONTH(ANALYZER_DATA!$H$2:$H$201)=A2)*ANALYZER_DATA!$E$2:$E$201)} -> 14914.65 | C2: =B3/B2-1 -> -0.060899183
A3: 2 | B3: {=SUMPRODUCT((MONTH(ANALYZER_DATA!$H$2:$H$201)=A3)*ANALYZER_DATA!$E$2:$E$201)} -> 14006.36 | C3: =B4/B3-1 -> 0.26051451
A4: 3 | B4: {=SUMPRODUCT((MONTH(ANALYZER_DATA!$H$2:$H$201)=A4)*ANALYZER_DATA!$E$2:$E$201)} -> 17655.22 | C4: =B5/B4-1 -> 0.25980475
A5: 4 | B5: {=SUMPRODUCT((MONTH(ANALYZER_DATA!$H$2:$H$201)=A5)*ANALYZER_DATA!$E$2:$E$201)} -> 22242.13 | C5: =B6/B5-1 -> -0.16791512
A6: 5 | B6: {=SUMPRODUCT((MONTH(ANALYZER_DATA!$H$2:$H$201)=A6)*ANALYZER_DATA!$E$2:$E$201)} -> 18507.34 | C6: =B7/B6-1 -> 0.090783981
A7: 6 | B7: {=SUMPRODUCT((MONTH(ANALYZER_DATA!$H$2:$H$201)=A7)*ANALYZER_DATA!$E$2:$E$201)} -> 20187.51 | C7: =B8/B7-1 -> -0.42493948
A8: 7 | B8: {=SUMPRODUCT((MONTH(ANALYZER_DATA!$H$2:$H$201)=A8)*ANALYZER_DATA!$E$2:$E$201)} -> 11609.04 | C8: =B9/B8-1 -> -0.13070331
A9: 8 | B9: {=SUMPRODUCT((MONTH(ANALYZER_DATA!$H$2:$H$201)=A9)*ANALYZER_DATA!$E$2:$E$201)} -> 10091.7 | C9: =B10/B9-1 -> 1.0346919
A10: 9 | B10: {=SUMPRODUCT((MONTH(ANALYZER_DATA!$H$2:$H$201)=A10)*ANALYZER_DATA!$E$2:$E$201)} -> 20533.5 | C10: =B11/B10-1 -> -0.30770497
A11: 10 | B11: {=SUMPRODUCT((MONTH(ANALYZER_DATA!$H$2:$H$201)=A11)*ANALYZER_DATA!$E$2:$E$201)} -> 14215.24 | C11: =B12/B11-1 -> 0.41643968
A12: 11 | B12: {=SUMPRODUCT((MONTH(ANALYZER_DATA!$H$2:$H$201)=A12)*ANALYZER_DATA!$E$2:$E$201)} -> 20135.03 | C12: =B13/B12-1 -> -0.44772667
A13: 12 | B13: {=SUMPRODUCT((MONTH(ANALYZER_DATA!$H$2:$H$201)=A13)*ANALYZER_DATA!$E$2:$E$201)} -> 11120.04 | C13: =D18/B13-1 -> -1

Sheet Descriptive Statistics
A1: Descriptive Statistics
A3: Mean | B3: 341.78879
A4: Standard Error | B4: 9.6419309
A5: Median | B5: 332.32
A6: Mode | B6: #N/A
A7: Standard Deviation | B7: 136.01617
A8: Sample Variance | B8: 18500.399
A9: Kurtosis | B9: 0.2506799
A10: Skewness | B10: 0.56597557
A11: Range | B11: 704.83
A12: Minimum | B12: 64.63
A13: Maximum | B13: 769.46
A14: Sum | B14: 68015.97
A15: Count | B15: 199

Sheet Regression Statistics
A1: SUMMARY OUTPUT
A3: Regression Statistics
A4: Multiple R | B4: 0.77340306
A5: R Square | B5: 0.5981523
A6: Adjusted R Square | B6: 0.59612277
A7: Standard Error | B7: 86.281231
A8: Observations | B8: 200
A10: ANOVA
B11: df | C11: SS | D11: MS | E11: F | F11: Significance F
A12: Regression | B12: 1 | C12: 2194058.2 | D12: 2194058.2 | E12: 294.72398 | F12: 4.6269368e-41
A13: Residual | B13: 198 | C13: 1474001.2 | D13: 7444.4507
A14: Total | B14: 199 | C14: 3668059.4
B16: Coefficients | C16: Standard Error | D16: t Stat | E16: P-value | F16: Lower 95% | G16: Upper 95% | H16: Lower 95.0% | I16: Upper 95.0%
A17: Intercept | B17: -1.0315505 | C17: 20.860617 | D17: -0.049449663 | E17: 0.9606108 | F17: -42.169052 | G17: 40.105951 | H17: -42.169052 | I17: 40.105951
A18: X Variable 1 | B18: 0.35085599 | C18: 0.020437189 | D18: 17.167527 | E18: 4.6269368e-41 | F18: 0.3105535 | G18: 0.39115848 | H18: 0.3105535 | I18: 0.39115848

Sheet REGION & PRODUCT SALES
A3: Sum of SALES | B3: Column Labels
A4: Row Labels | B4: Office Supplies | C4: Furniture | D4: Electronics | E4: Clothing | F4: Books | G4: Grand Total
A5: Central | B5: 8472.72 | C5: 4876.96 | D5: 6621.24 | E5: 12200.26 | F5: 11297.15 | G5: 43468.33
A6: East | B6: 8189.22 | C6: 7592.34 | D6: 2869.54 | E6: 2401.45 | F6: 11389.09 | G6: 32441.64
A7: North | B7: 3345.8 | C7: 6978.08 | D7: 8191.71 | E7: 8422.82 | F7: 8037.01 | G7: 34975.42
A8: South | B8: 2295.32 | C8: 7982.73 | D8: 11989.07 | E8: 8393.63 | F8: 9588.04 | G8: 40248.79
A9: West | B9: 6327.76 | C9: 9182.78 | D9: 11372.44 | E9: 10509.43 | F9: 6691.17 | G9: 44083.58
A10: Grand Total | B10: 28630.82 | C10: 36612.89 | D10: 41044 | E10: 41927.59 | F10: 47002.46 | G10: 195217.76

Sheet REGION PERFORMANCE
A3: Row Labels | B3: Sum of SALES
A4: Central | B4: 43468.33
A5: East | B5: 32441.64
A6: North | B6: 34975.42
A7: South | B7: 40248.79
A8: West | B8: 44083.58
A9: Grand Total | B9: 195217.76

Sheet PRODUCT PERFORMANCE
A3: Row Labels | B3: Sum of SALES
A4: Books | B4: 47002.46
A5: Clothing | B5: 41927.59
A6: Electronics | B6: 41044
A7: Furniture | B7: 36612.89
A8: Office Supplies | B8: 28630.82
A9: Grand Total | B9: 195217.76

Sheet PIVOT TABLES
A1: REGION & PRODUCT SALES | I1: REGION PERFORMANCE | L1: PRODUCT PERFORMANCE | O1: MONTHLY SALES
A2: Sum of SALES | B2: Column Labels | I2: Row Labels | J2: Sum of SALES | L2: Row Labels | M2: Sum of SALES | O2: Row Labels | P2: Sum of SALES
A3: Row Labels | B3: Office Supplies | C3: Furniture | D3: Electronics | E3: Clothing | F3: Books | G3: Grand Total | I3: Central | J3: 43468.33 | L3: Books | M3: 47002.46 | O3: Jan | P3: 14914.65
A4: Central | B4: 8472.72 | C4: 4876.96 | D4: 6621.24 | E4: 12200.26 | F4: 11297.15 | G4: 43468.33 | I4: East | J4: 32441.64 | L4: Clothing | M4: 41927.59 | O4: Feb | P4: 14006.36
A5: East | B5: 8189.22 | C5: 7592.34 | D5: 2869.54 | E5: 2401.45 | F5: 11389.09 | G5: 32441.64 | I5: North | J5: 34975.42 | L5: Electronics | M5: 41044 | O5: Mar | P5: 17655.22
A6: North | B6: 3345.8 | C6: 6978.08 | D6: 8191.71 | E6: 8422.82 | F6: 8037.01 | G6: 34975.42 | I6: South | J6: 40248.79 | L6: Furniture | M6: 36612.89 | O6: Apr | P6: 22242.13
A7: South | B7: 2295.32 | C7: 7982.73 | D7: 11989.07 | E7: 8393.63 | F7: 9588.04 | G7: 40248.79 | I7: West | J7: 44083.58 | L7: Office Supplies | M7: 28630.82 | O7: May | P7: 18507.34
A8: West | B8: 6327.76 | C8: 9182.78 | D8: 11372.44 | E8: 10509.43 | F8: 6691.17 | G8: 44083.58 | I8: Grand Total | J8: 195217.76 | L8: Grand Total | M8: 195217.76 | O8: Jun | P8: 20187.51
A9: Grand Total | B9: 28630.82 | C9: 36612.89 | D9: 41044 | E9: 41927.59 | F9: 47002.46 | G9: 195217.76 | O9: Jul | P9: 11609.04
O10: Aug | P10: 10091.7
O11: Sep | P11: 20533.5
O12: Oct | P12: 14215.24
O13: Nov | P13: 20135.03
O14: Dec | P14: 11120.04
O15: Grand Total | P15: 195217.76
A24: KPI_Sum of PROFIT | D24: KPI_Sum of QUANTITY
A25: Sum of PROFIT | D25: Sum of QUANTITY
A26: 68287.01 | D26: 1999
A28: KPI_TOP_CUSTOMER | D28: KPI_TOP_PRODUCT
A29: TOP_CUSTOMERS | B29: Sum of TOTAL_PURCHASE | D29: TOP PRODUCT | E29: Sum of SALES
A30: David Anderson | B30: 40881.14 | D30: Office Supplies | E30: 28630.82
A31: David Brown | B31: 93568.88 | D31: Furniture | E31: 36612.89
A32: David Davis | B32: 26809.28 | D32: Electronics | E32: 41044
A33: David Smith | B33: 12445.18 | D33: Clothing | E33: 41927.59
A34: David Thomas | B34: 49422.75 | D34: Books | E34: 47002.46
A35: Emma Davis | B35: 89138.87 | D35: Grand Total | E35: 195217.76
A36: Emma Taylor | B36: 41542.05
A37: Emma Wilson | B37: 50808.8
A38: James Davis | B38: 49136.74
A39: James Taylor | B39: 29569.46
A40: James Wilson | B40: 172137.04
A41: John Brown | B41: 17689.51
A42: Linda Brown | B42: 35746.67
A43: Linda Davis | B43: 3419.2
A44: Linda Jackson | B44: 25500.9
A45: Linda Moore | B45: 16666.18
A46: Linda Taylor | B46: 54750.54
A47: Linda Wilson | B47: 55747.07
... A57: Grand Total | B57: 1458721.3
